Traceback (most recent call last):
  File "/Users/dsmith4/anaconda3/lib/python3.10/site-packages/jupyter_cache/executors/utils.py", line 58, in single_nb_execution
    executenb(
  File "/Users/dsmith4/anaconda3/lib/python3.10/site-packages/nbclient/client.py", line 1204, in execute
    return NotebookClient(nb=nb, resources=resources, km=km, **kwargs).execute()
  File "/Users/dsmith4/anaconda3/lib/python3.10/site-packages/nbclient/util.py", line 84, in wrapped
    return just_run(coro(*args, **kwargs))
  File "/Users/dsmith4/anaconda3/lib/python3.10/site-packages/nbclient/util.py", line 62, in just_run
    return loop.run_until_complete(coro)
  File "/Users/dsmith4/anaconda3/lib/python3.10/asyncio/base_events.py", line 649, in run_until_complete
    return future.result()
  File "/Users/dsmith4/anaconda3/lib/python3.10/site-packages/nbclient/client.py", line 663, in async_execute
    await self.async_execute_cell(
  File "/Users/dsmith4/anaconda3/lib/python3.10/site-packages/nbclient/client.py", line 965, in async_execute_cell
    await self._check_raise_for_error(cell, cell_index, exec_reply)
  File "/Users/dsmith4/anaconda3/lib/python3.10/site-packages/nbclient/client.py", line 862, in _check_raise_for_error
    raise CellExecutionError.from_cell_and_msg(cell, exec_reply_content)
nbclient.exceptions.CellExecutionError: An error occurred while executing the following cell:
------------------
# 3D plot of a spacetime diagram with x, ct, and y
plt.figure(figsize=(5,5))
plt.arrow(0,0,1,0,head_width=0.1)
plt.arrow(0,0,0,1,head_width=0.1)

plt.arrow(-0.5,-0.5,1,0,head_width=0.1)
plt.arrow(-0.5,-0.5,0,1,head_width=0.1)

plt.arrow(0.2,-0.25,0.75,0,head_width=0.05)
ax = plt.gca()
ax.get_xaxis().set_visible(False)
ax.get_yaxis().set_visible(False)
plt.axis([-1,2,-2,2])
ax.text(0.15, 1, "S")
ax.text(-0.05, 1.2, "ct")
ax.text(1.2, 0, "x")
ax.text(1.1, -0.25, "v_R")
ax.text(-0.35, .5, "S'")
ax.text(-.55, .7, "ct'")
ax.text(.7, -0.5, "x'")

glue("basicSTfig", fig, display=False)
------------------

[0;31m---------------------------------------------------------------------------[0m
[0;31mNameError[0m                                 Traceback (most recent call last)
Cell [0;32mIn[3], line 22[0m
[1;32m     19[0m ax[38;5;241m.[39mtext([38;5;241m-[39m[38;5;241m.55[39m, [38;5;241m.7[39m, [38;5;124m"[39m[38;5;124mct[39m[38;5;124m'[39m[38;5;124m"[39m)
[1;32m     20[0m ax[38;5;241m.[39mtext([38;5;241m.7[39m, [38;5;241m-[39m[38;5;241m0.5[39m, [38;5;124m"[39m[38;5;124mx[39m[38;5;124m'[39m[38;5;124m"[39m)
[0;32m---> 22[0m glue([38;5;124m"[39m[38;5;124mbasicSTfig[39m[38;5;124m"[39m, [43mfig[49m, display[38;5;241m=[39m[38;5;28;01mFalse[39;00m)

[0;31mNameError[0m: name 'fig' is not defined
NameError: name 'fig' is not defined

