Traceback (most recent call last):
  File "/Users/dsmith4/anaconda3/lib/python3.10/site-packages/jupyter_cache/executors/utils.py", line 58, in single_nb_execution
    executenb(
  File "/Users/dsmith4/anaconda3/lib/python3.10/site-packages/nbclient/client.py", line 1204, in execute
    return NotebookClient(nb=nb, resources=resources, km=km, **kwargs).execute()
  File "/Users/dsmith4/anaconda3/lib/python3.10/site-packages/nbclient/util.py", line 84, in wrapped
    return just_run(coro(*args, **kwargs))
  File "/Users/dsmith4/anaconda3/lib/python3.10/site-packages/nbclient/util.py", line 62, in just_run
    return loop.run_until_complete(coro)
  File "/Users/dsmith4/anaconda3/lib/python3.10/asyncio/base_events.py", line 649, in run_until_complete
    return future.result()
  File "/Users/dsmith4/anaconda3/lib/python3.10/site-packages/nbclient/client.py", line 663, in async_execute
    await self.async_execute_cell(
  File "/Users/dsmith4/anaconda3/lib/python3.10/site-packages/nbclient/client.py", line 965, in async_execute_cell
    await self._check_raise_for_error(cell, cell_index, exec_reply)
  File "/Users/dsmith4/anaconda3/lib/python3.10/site-packages/nbclient/client.py", line 862, in _check_raise_for_error
    raise CellExecutionError.from_cell_and_msg(cell, exec_reply_content)
nbclient.exceptions.CellExecutionError: An error occurred while executing the following cell:
------------------
x = np.array([0.00727916669899,0.291343510515,1.00907060776,1.72012215409])
y = np.array([0.000143505126673,0.000682172607672,0.00198582395962,0.00341847052919])+0.057
z = np.polyfit(x, y, 2)
f = np.poly1d(z)
x_new = np.linspace(x[0], x[-1], 50)
y_new = f(x_new)

plt.figure(figsize=(8,8))
plt.plot(x,y,'bs',label="Original Data")
plt.plot(new_x,new_y,"k:",label="Linear Fit")
plt.xlabel(r"1-$\cos{\theta}$")
plt.ylabel("1/E scattered (1/keV)")
plt.title("Testing Compton Scattering Hypothesis")
plt.show()
------------------

[0;31m---------------------------------------------------------------------------[0m
[0;31mNameError[0m                                 Traceback (most recent call last)
Cell [0;32mIn[5], line 10[0m
[1;32m      8[0m plt[38;5;241m.[39mfigure(figsize[38;5;241m=[39m([38;5;241m8[39m,[38;5;241m8[39m))
[1;32m      9[0m plt[38;5;241m.[39mplot(x,y,[38;5;124m'[39m[38;5;124mbs[39m[38;5;124m'[39m,label[38;5;241m=[39m[38;5;124m"[39m[38;5;124mOriginal Data[39m[38;5;124m"[39m)
[0;32m---> 10[0m plt[38;5;241m.[39mplot([43mnew_x[49m,new_y,[38;5;124m"[39m[38;5;124mk:[39m[38;5;124m"[39m,label[38;5;241m=[39m[38;5;124m"[39m[38;5;124mLinear Fit[39m[38;5;124m"[39m)
[1;32m     11[0m plt[38;5;241m.[39mxlabel([38;5;124mr[39m[38;5;124m"[39m[38;5;124m1-$[39m[38;5;124m\[39m[38;5;124mcos[39m[38;5;124m{[39m[38;5;124m\[39m[38;5;124mtheta}$[39m[38;5;124m"[39m)
[1;32m     12[0m plt[38;5;241m.[39mylabel([38;5;124m"[39m[38;5;124m1/E scattered (1/keV)[39m[38;5;124m"[39m)

[0;31mNameError[0m: name 'new_x' is not defined
NameError: name 'new_x' is not defined

